{"trial_id": "1", "hyperparameters": {"space": [{"class_name": "Int", "config": {"name": "units", "default": null, "conditions": [], "min_value": 32, "max_value": 256, "step": 32, "sampling": "linear"}}, {"class_name": "Float", "config": {"name": "dropout", "default": 0.2, "conditions": [], "min_value": 0.2, "max_value": 0.5, "step": 0.1, "sampling": "linear"}}, {"class_name": "Int", "config": {"name": "units2", "default": null, "conditions": [], "min_value": 32, "max_value": 256, "step": 32, "sampling": "linear"}}, {"class_name": "Float", "config": {"name": "dropout2", "default": 0.2, "conditions": [], "min_value": 0.2, "max_value": 0.5, "step": 0.1, "sampling": "linear"}}], "values": {"units": 64, "dropout": 0.30000000000000004, "units2": 192, "dropout2": 0.30000000000000004}}, "metrics": {"metrics": {}}, "score": null, "best_step": 0, "status": "FAILED", "message": "Traceback (most recent call last):\n  File \"C:\\Users\\mgula\\anaconda3\\Lib\\site-packages\\keras_tuner\\src\\engine\\base_tuner.py\", line 274, in _try_run_and_update_trial\n    self._run_and_update_trial(trial, *fit_args, **fit_kwargs)\n  File \"C:\\Users\\mgula\\anaconda3\\Lib\\site-packages\\keras_tuner\\src\\engine\\base_tuner.py\", line 239, in _run_and_update_trial\n    results = self.run_trial(trial, *fit_args, **fit_kwargs)\n              ^^^^^^^^^^^^^^^^^^^^^^^^^^^^^^^^^^^^^^^^^^^^^^\n  File \"C:\\Users\\mgula\\anaconda3\\Lib\\site-packages\\keras_tuner\\src\\engine\\tuner.py\", line 314, in run_trial\n    obj_value = self._build_and_fit_model(trial, *args, **copied_kwargs)\n                ^^^^^^^^^^^^^^^^^^^^^^^^^^^^^^^^^^^^^^^^^^^^^^^^^^^^^^^^\n  File \"C:\\Users\\mgula\\anaconda3\\Lib\\site-packages\\keras_tuner\\src\\engine\\tuner.py\", line 233, in _build_and_fit_model\n    results = self.hypermodel.fit(hp, model, *args, **kwargs)\n              ^^^^^^^^^^^^^^^^^^^^^^^^^^^^^^^^^^^^^^^^^^^^^^^\n  File \"C:\\Users\\mgula\\anaconda3\\Lib\\site-packages\\keras_tuner\\src\\engine\\hypermodel.py\", line 149, in fit\n    return model.fit(*args, **kwargs)\n           ^^^^^^^^^^^^^^^^^^^^^^^^^^\n  File \"C:\\Users\\mgula\\anaconda3\\Lib\\site-packages\\keras\\src\\utils\\traceback_utils.py\", line 122, in error_handler\n    raise e.with_traceback(filtered_tb) from None\n  File \"C:\\Users\\mgula\\anaconda3\\Lib\\site-packages\\keras\\src\\trainers\\data_adapters\\data_adapter_utils.py\", line 114, in check_data_cardinality\n    raise ValueError(msg)\nValueError: Data cardinality is ambiguous. Make sure all arrays contain the same number of samples.'x' sizes: 496\n'y' sizes: 4960\n\n"}